[2023-05-10T04:50:04.748+0000] {taskinstance.py:1125} INFO - Dependencies all met for dep_context=non-requeueable deps ti=<TaskInstance: testing_stuff.run_remote_script scheduled__2023-05-10T04:40:00+00:00 [queued]>
[2023-05-10T04:50:04.756+0000] {taskinstance.py:1125} INFO - Dependencies all met for dep_context=requeueable deps ti=<TaskInstance: testing_stuff.run_remote_script scheduled__2023-05-10T04:40:00+00:00 [queued]>
[2023-05-10T04:50:04.757+0000] {taskinstance.py:1331} INFO - Starting attempt 1 of 2
[2023-05-10T04:50:04.773+0000] {taskinstance.py:1350} INFO - Executing <Task(BashOperator): run_remote_script> on 2023-05-10 04:40:00+00:00
[2023-05-10T04:50:04.780+0000] {standard_task_runner.py:57} INFO - Started process 631 to run task
[2023-05-10T04:50:04.786+0000] {standard_task_runner.py:84} INFO - Running: ['***', 'tasks', 'run', 'testing_stuff', 'run_remote_script', 'scheduled__2023-05-10T04:40:00+00:00', '--job-id', '41', '--raw', '--subdir', 'DAGS_FOLDER/test.py', '--cfg-path', '/tmp/tmpnjczti2z']
[2023-05-10T04:50:04.787+0000] {standard_task_runner.py:85} INFO - Job 41: Subtask run_remote_script
[2023-05-10T04:50:04.857+0000] {task_command.py:410} INFO - Running <TaskInstance: testing_stuff.run_remote_script scheduled__2023-05-10T04:40:00+00:00 [running]> on host 448394b5800f
[2023-05-10T04:50:04.960+0000] {taskinstance.py:1570} INFO - Exporting env vars: AIRFLOW_CTX_DAG_EMAIL='***@example.com' AIRFLOW_CTX_DAG_OWNER='***' AIRFLOW_CTX_DAG_ID='testing_stuff' AIRFLOW_CTX_TASK_ID='run_remote_script' AIRFLOW_CTX_EXECUTION_DATE='2023-05-10T04:40:00+00:00' AIRFLOW_CTX_TRY_NUMBER='1' AIRFLOW_CTX_DAG_RUN_ID='scheduled__2023-05-10T04:40:00+00:00'
[2023-05-10T04:50:04.962+0000] {subprocess.py:63} INFO - Tmp dir root location: 
 /tmp
[2023-05-10T04:50:04.964+0000] {subprocess.py:75} INFO - Running command: ['/bin/bash', '-c', '#!/bin/bash\n\ndocker ps -a\ndocker ps\n\nll']
[2023-05-10T04:50:04.976+0000] {subprocess.py:86} INFO - Output:
[2023-05-10T04:50:05.168+0000] {subprocess.py:93} INFO - Cannot connect to the Docker daemon at unix:///var/run/docker.sock. Is the docker daemon running?
[2023-05-10T04:50:05.216+0000] {subprocess.py:93} INFO - Cannot connect to the Docker daemon at unix:///var/run/docker.sock. Is the docker daemon running?
[2023-05-10T04:50:05.222+0000] {subprocess.py:93} INFO - /bin/bash: line 6: ll: command not found
[2023-05-10T04:50:05.223+0000] {subprocess.py:97} INFO - Command exited with return code 127
[2023-05-10T04:50:05.247+0000] {taskinstance.py:1847} ERROR - Task failed with exception
Traceback (most recent call last):
  File "/home/airflow/.local/lib/python3.7/site-packages/airflow/operators/bash.py", line 211, in execute
    f"Bash command failed. The command returned a non-zero exit code {result.exit_code}."
airflow.exceptions.AirflowException: Bash command failed. The command returned a non-zero exit code 127.
[2023-05-10T04:50:05.255+0000] {taskinstance.py:1373} INFO - Marking task as UP_FOR_RETRY. dag_id=testing_stuff, task_id=run_remote_script, execution_date=20230510T044000, start_date=20230510T045004, end_date=20230510T045005
[2023-05-10T04:50:05.270+0000] {standard_task_runner.py:109} ERROR - Failed to execute job 41 for task run_remote_script (Bash command failed. The command returned a non-zero exit code 127.; 631)
[2023-05-10T04:50:05.324+0000] {local_task_job_runner.py:232} INFO - Task exited with return code 1
[2023-05-10T04:50:05.380+0000] {taskinstance.py:2674} INFO - 0 downstream tasks scheduled from follow-on schedule check
